[2024-10-20T17:06:21.969+0000] {taskinstance.py:1159} INFO - Dependencies all met for dep_context=non-requeueable deps ti=<TaskInstance: covid_wave_3_etl.transform manual__2024-10-20T17:04:13.362044+00:00 [queued]>
[2024-10-20T17:06:21.979+0000] {taskinstance.py:1159} INFO - Dependencies all met for dep_context=requeueable deps ti=<TaskInstance: covid_wave_3_etl.transform manual__2024-10-20T17:04:13.362044+00:00 [queued]>
[2024-10-20T17:06:21.979+0000] {taskinstance.py:1361} INFO - Starting attempt 1 of 2
[2024-10-20T17:06:21.995+0000] {taskinstance.py:1382} INFO - Executing <Task(PythonOperator): transform> on 2024-10-20 17:04:13.362044+00:00
[2024-10-20T17:06:22.003+0000] {standard_task_runner.py:57} INFO - Started process 219 to run task
[2024-10-20T17:06:22.006+0000] {standard_task_runner.py:84} INFO - Running: ['***', 'tasks', 'run', 'covid_wave_3_etl', 'transform', 'manual__2024-10-20T17:04:13.362044+00:00', '--job-id', '509', '--raw', '--subdir', 'DAGS_FOLDER/covid_wave_3.py', '--cfg-path', '/tmp/tmprm_zlppm']
[2024-10-20T17:06:22.008+0000] {standard_task_runner.py:85} INFO - Job 509: Subtask transform
[2024-10-20T17:06:22.066+0000] {task_command.py:416} INFO - Running <TaskInstance: covid_wave_3_etl.transform manual__2024-10-20T17:04:13.362044+00:00 [running]> on host 0d584f57979f
[2024-10-20T17:06:22.144+0000] {taskinstance.py:1662} INFO - Exporting env vars: AIRFLOW_CTX_DAG_OWNER='***' AIRFLOW_CTX_DAG_ID='covid_wave_3_etl' AIRFLOW_CTX_TASK_ID='transform' AIRFLOW_CTX_EXECUTION_DATE='2024-10-20T17:04:13.362044+00:00' AIRFLOW_CTX_TRY_NUMBER='1' AIRFLOW_CTX_DAG_RUN_ID='manual__2024-10-20T17:04:13.362044+00:00'
[2024-10-20T17:06:22.182+0000] {taskinstance.py:1937} ERROR - Task failed with exception
Traceback (most recent call last):
  File "/home/airflow/.local/lib/python3.8/site-packages/airflow/operators/python.py", line 192, in execute
    return_value = self.execute_callable()
  File "/home/airflow/.local/lib/python3.8/site-packages/airflow/operators/python.py", line 209, in execute_callable
    return self.python_callable(*self.op_args, **self.op_kwargs)
  File "/opt/airflow/dags/covid_wave_3.py", line 20, in transform_data
    df = pd.DataFrame(data)
  File "/home/airflow/.local/lib/python3.8/site-packages/pandas/core/frame.py", line 709, in __init__
    mgr = dict_to_mgr(data, index, columns, dtype=dtype, copy=copy, typ=manager)
  File "/home/airflow/.local/lib/python3.8/site-packages/pandas/core/internals/construction.py", line 481, in dict_to_mgr
    return arrays_to_mgr(arrays, columns, index, dtype=dtype, typ=typ, consolidate=copy)
  File "/home/airflow/.local/lib/python3.8/site-packages/pandas/core/internals/construction.py", line 115, in arrays_to_mgr
    index = _extract_index(arrays)
  File "/home/airflow/.local/lib/python3.8/site-packages/pandas/core/internals/construction.py", line 658, in _extract_index
    raise ValueError(
ValueError: Mixing dicts with non-Series may lead to ambiguous ordering.
[2024-10-20T17:06:22.195+0000] {taskinstance.py:1400} INFO - Marking task as UP_FOR_RETRY. dag_id=covid_wave_3_etl, task_id=transform, execution_date=20241020T170413, start_date=20241020T170621, end_date=20241020T170622
[2024-10-20T17:06:22.211+0000] {standard_task_runner.py:104} ERROR - Failed to execute job 509 for task transform (Mixing dicts with non-Series may lead to ambiguous ordering.; 219)
[2024-10-20T17:06:22.260+0000] {local_task_job_runner.py:228} INFO - Task exited with return code 1
[2024-10-20T17:06:22.340+0000] {taskinstance.py:2778} INFO - 0 downstream tasks scheduled from follow-on schedule check
