[2024-10-20T17:01:44.259+0000] {taskinstance.py:1159} INFO - Dependencies all met for dep_context=non-requeueable deps ti=<TaskInstance: covid_wave_3_etl.transform scheduled__2024-09-17T00:00:00+00:00 [queued]>
[2024-10-20T17:01:44.269+0000] {taskinstance.py:1159} INFO - Dependencies all met for dep_context=requeueable deps ti=<TaskInstance: covid_wave_3_etl.transform scheduled__2024-09-17T00:00:00+00:00 [queued]>
[2024-10-20T17:01:44.270+0000] {taskinstance.py:1361} INFO - Starting attempt 1 of 2
[2024-10-20T17:01:44.284+0000] {taskinstance.py:1382} INFO - Executing <Task(PythonOperator): transform> on 2024-09-17 00:00:00+00:00
[2024-10-20T17:01:44.293+0000] {standard_task_runner.py:57} INFO - Started process 124 to run task
[2024-10-20T17:01:44.299+0000] {standard_task_runner.py:84} INFO - Running: ['***', 'tasks', 'run', 'covid_wave_3_etl', 'transform', 'scheduled__2024-09-17T00:00:00+00:00', '--job-id', '498', '--raw', '--subdir', 'DAGS_FOLDER/covid_wave_3.py', '--cfg-path', '/tmp/tmpnlrl6xu4']
[2024-10-20T17:01:44.300+0000] {standard_task_runner.py:85} INFO - Job 498: Subtask transform
[2024-10-20T17:01:44.362+0000] {task_command.py:416} INFO - Running <TaskInstance: covid_wave_3_etl.transform scheduled__2024-09-17T00:00:00+00:00 [running]> on host 0d584f57979f
[2024-10-20T17:01:44.440+0000] {taskinstance.py:1662} INFO - Exporting env vars: AIRFLOW_CTX_DAG_OWNER='***' AIRFLOW_CTX_DAG_ID='covid_wave_3_etl' AIRFLOW_CTX_TASK_ID='transform' AIRFLOW_CTX_EXECUTION_DATE='2024-09-17T00:00:00+00:00' AIRFLOW_CTX_TRY_NUMBER='1' AIRFLOW_CTX_DAG_RUN_ID='scheduled__2024-09-17T00:00:00+00:00'
[2024-10-20T17:01:44.476+0000] {taskinstance.py:1937} ERROR - Task failed with exception
Traceback (most recent call last):
  File "/home/airflow/.local/lib/python3.8/site-packages/airflow/operators/python.py", line 192, in execute
    return_value = self.execute_callable()
  File "/home/airflow/.local/lib/python3.8/site-packages/airflow/operators/python.py", line 209, in execute_callable
    return self.python_callable(*self.op_args, **self.op_kwargs)
  File "/opt/airflow/dags/covid_wave_3.py", line 20, in transform_data
    df = pd.DataFrame(data)
  File "/home/airflow/.local/lib/python3.8/site-packages/pandas/core/frame.py", line 709, in __init__
    mgr = dict_to_mgr(data, index, columns, dtype=dtype, copy=copy, typ=manager)
  File "/home/airflow/.local/lib/python3.8/site-packages/pandas/core/internals/construction.py", line 481, in dict_to_mgr
    return arrays_to_mgr(arrays, columns, index, dtype=dtype, typ=typ, consolidate=copy)
  File "/home/airflow/.local/lib/python3.8/site-packages/pandas/core/internals/construction.py", line 115, in arrays_to_mgr
    index = _extract_index(arrays)
  File "/home/airflow/.local/lib/python3.8/site-packages/pandas/core/internals/construction.py", line 658, in _extract_index
    raise ValueError(
ValueError: Mixing dicts with non-Series may lead to ambiguous ordering.
[2024-10-20T17:01:44.489+0000] {taskinstance.py:1400} INFO - Marking task as UP_FOR_RETRY. dag_id=covid_wave_3_etl, task_id=transform, execution_date=20240917T000000, start_date=20241020T170144, end_date=20241020T170144
[2024-10-20T17:01:44.502+0000] {standard_task_runner.py:104} ERROR - Failed to execute job 498 for task transform (Mixing dicts with non-Series may lead to ambiguous ordering.; 124)
[2024-10-20T17:01:44.551+0000] {local_task_job_runner.py:228} INFO - Task exited with return code 1
[2024-10-20T17:01:44.576+0000] {taskinstance.py:2778} INFO - 0 downstream tasks scheduled from follow-on schedule check
