[2024-10-20T16:31:58.203+0000] {taskinstance.py:1159} INFO - Dependencies all met for dep_context=non-requeueable deps ti=<TaskInstance: covid_etl.load manual__2024-10-20T16:31:46.303995+00:00 [queued]>
[2024-10-20T16:31:58.214+0000] {taskinstance.py:1159} INFO - Dependencies all met for dep_context=requeueable deps ti=<TaskInstance: covid_etl.load manual__2024-10-20T16:31:46.303995+00:00 [queued]>
[2024-10-20T16:31:58.215+0000] {taskinstance.py:1361} INFO - Starting attempt 1 of 2
[2024-10-20T16:31:58.232+0000] {taskinstance.py:1382} INFO - Executing <Task(PythonOperator): load> on 2024-10-20 16:31:46.303995+00:00
[2024-10-20T16:31:58.240+0000] {standard_task_runner.py:57} INFO - Started process 108 to run task
[2024-10-20T16:31:58.244+0000] {standard_task_runner.py:84} INFO - Running: ['***', 'tasks', 'run', 'covid_etl', 'load', 'manual__2024-10-20T16:31:46.303995+00:00', '--job-id', '438', '--raw', '--subdir', 'DAGS_FOLDER/covid_dag.py', '--cfg-path', '/tmp/tmp3sjawupk']
[2024-10-20T16:31:58.245+0000] {standard_task_runner.py:85} INFO - Job 438: Subtask load
[2024-10-20T16:31:58.302+0000] {task_command.py:416} INFO - Running <TaskInstance: covid_etl.load manual__2024-10-20T16:31:46.303995+00:00 [running]> on host ffa6482d0454
[2024-10-20T16:31:58.408+0000] {taskinstance.py:1662} INFO - Exporting env vars: AIRFLOW_CTX_DAG_OWNER='***' AIRFLOW_CTX_DAG_ID='covid_etl' AIRFLOW_CTX_TASK_ID='load' AIRFLOW_CTX_EXECUTION_DATE='2024-10-20T16:31:46.303995+00:00' AIRFLOW_CTX_TRY_NUMBER='1' AIRFLOW_CTX_DAG_RUN_ID='manual__2024-10-20T16:31:46.303995+00:00'
[2024-10-20T16:31:58.438+0000] {taskinstance.py:1937} ERROR - Task failed with exception
Traceback (most recent call last):
  File "/home/airflow/.local/lib/python3.8/site-packages/airflow/operators/python.py", line 192, in execute
    return_value = self.execute_callable()
  File "/home/airflow/.local/lib/python3.8/site-packages/airflow/operators/python.py", line 209, in execute_callable
    return self.python_callable(*self.op_args, **self.op_kwargs)
  File "/opt/airflow/dags/covid_dag.py", line 35, in load_to_db
    df.to_sql('covid_cases_by_province', con=engine, if_exists='replace', index=False)
  File "/home/airflow/.local/lib/python3.8/site-packages/pandas/core/generic.py", line 2878, in to_sql
    return sql.to_sql(
  File "/home/airflow/.local/lib/python3.8/site-packages/pandas/io/sql.py", line 768, in to_sql
    with pandasSQL_builder(con, schema=schema, need_transaction=True) as pandas_sql:
  File "/home/airflow/.local/lib/python3.8/site-packages/pandas/io/sql.py", line 832, in pandasSQL_builder
    return SQLDatabase(con, schema, need_transaction)
  File "/home/airflow/.local/lib/python3.8/site-packages/pandas/io/sql.py", line 1539, in __init__
    con = self.exit_stack.enter_context(con.connect())
  File "/home/airflow/.local/lib/python3.8/site-packages/sqlalchemy/engine/base.py", line 3325, in connect
    return self._connection_cls(self, close_with_result=close_with_result)
  File "/home/airflow/.local/lib/python3.8/site-packages/sqlalchemy/engine/base.py", line 96, in __init__
    else engine.raw_connection()
  File "/home/airflow/.local/lib/python3.8/site-packages/sqlalchemy/engine/base.py", line 3404, in raw_connection
    return self._wrap_pool_connect(self.pool.connect, _connection)
  File "/home/airflow/.local/lib/python3.8/site-packages/sqlalchemy/engine/base.py", line 3371, in _wrap_pool_connect
    return fn()
  File "/home/airflow/.local/lib/python3.8/site-packages/sqlalchemy/pool/base.py", line 327, in connect
    return _ConnectionFairy._checkout(self)
  File "/home/airflow/.local/lib/python3.8/site-packages/sqlalchemy/pool/base.py", line 894, in _checkout
    fairy = _ConnectionRecord.checkout(pool)
  File "/home/airflow/.local/lib/python3.8/site-packages/sqlalchemy/pool/base.py", line 493, in checkout
    rec = pool._do_get()
  File "/home/airflow/.local/lib/python3.8/site-packages/sqlalchemy/pool/impl.py", line 146, in _do_get
    self._dec_overflow()
  File "/home/airflow/.local/lib/python3.8/site-packages/sqlalchemy/util/langhelpers.py", line 70, in __exit__
    compat.raise_(
  File "/home/airflow/.local/lib/python3.8/site-packages/sqlalchemy/util/compat.py", line 211, in raise_
    raise exception
  File "/home/airflow/.local/lib/python3.8/site-packages/sqlalchemy/pool/impl.py", line 143, in _do_get
    return self._create_connection()
  File "/home/airflow/.local/lib/python3.8/site-packages/sqlalchemy/pool/base.py", line 273, in _create_connection
    return _ConnectionRecord(self)
  File "/home/airflow/.local/lib/python3.8/site-packages/sqlalchemy/pool/base.py", line 388, in __init__
    self.__connect()
  File "/home/airflow/.local/lib/python3.8/site-packages/sqlalchemy/pool/base.py", line 691, in __connect
    pool.logger.debug("Error on connect(): %s", e)
  File "/home/airflow/.local/lib/python3.8/site-packages/sqlalchemy/util/langhelpers.py", line 70, in __exit__
    compat.raise_(
  File "/home/airflow/.local/lib/python3.8/site-packages/sqlalchemy/util/compat.py", line 211, in raise_
    raise exception
  File "/home/airflow/.local/lib/python3.8/site-packages/sqlalchemy/pool/base.py", line 686, in __connect
    self.dbapi_connection = connection = pool._invoke_creator(self)
  File "/home/airflow/.local/lib/python3.8/site-packages/sqlalchemy/engine/create.py", line 574, in connect
    return dialect.connect(*cargs, **cparams)
  File "/home/airflow/.local/lib/python3.8/site-packages/sqlalchemy/engine/default.py", line 598, in connect
    return self.dbapi.connect(*cargs, **cparams)
TypeError: __init__() got an unexpected keyword argument 'allowPublicKeyRetrieval'
[2024-10-20T16:31:58.456+0000] {taskinstance.py:1400} INFO - Marking task as UP_FOR_RETRY. dag_id=covid_etl, task_id=load, execution_date=20241020T163146, start_date=20241020T163158, end_date=20241020T163158
[2024-10-20T16:31:58.506+0000] {standard_task_runner.py:104} ERROR - Failed to execute job 438 for task load (__init__() got an unexpected keyword argument 'allowPublicKeyRetrieval'; 108)
[2024-10-20T16:31:58.537+0000] {local_task_job_runner.py:228} INFO - Task exited with return code 1
[2024-10-20T16:31:58.557+0000] {taskinstance.py:2778} INFO - 0 downstream tasks scheduled from follow-on schedule check
