[2024-10-20T17:14:40.323+0000] {taskinstance.py:1159} INFO - Dependencies all met for dep_context=non-requeueable deps ti=<TaskInstance: covid_wave_3_etl.load scheduled__2024-09-01T00:00:00+00:00 [queued]>
[2024-10-20T17:14:40.334+0000] {taskinstance.py:1159} INFO - Dependencies all met for dep_context=requeueable deps ti=<TaskInstance: covid_wave_3_etl.load scheduled__2024-09-01T00:00:00+00:00 [queued]>
[2024-10-20T17:14:40.335+0000] {taskinstance.py:1361} INFO - Starting attempt 2 of 2
[2024-10-20T17:14:40.349+0000] {taskinstance.py:1382} INFO - Executing <Task(PythonOperator): load> on 2024-09-01 00:00:00+00:00
[2024-10-20T17:14:40.356+0000] {standard_task_runner.py:57} INFO - Started process 93 to run task
[2024-10-20T17:14:40.359+0000] {standard_task_runner.py:84} INFO - Running: ['***', 'tasks', 'run', 'covid_wave_3_etl', 'load', 'scheduled__2024-09-01T00:00:00+00:00', '--job-id', '586', '--raw', '--subdir', 'DAGS_FOLDER/covid_wave_3.py', '--cfg-path', '/tmp/tmp7hvhez7d']
[2024-10-20T17:14:40.361+0000] {standard_task_runner.py:85} INFO - Job 586: Subtask load
[2024-10-20T17:14:40.406+0000] {task_command.py:416} INFO - Running <TaskInstance: covid_wave_3_etl.load scheduled__2024-09-01T00:00:00+00:00 [running]> on host 390701efcf86
[2024-10-20T17:14:40.487+0000] {taskinstance.py:1662} INFO - Exporting env vars: AIRFLOW_CTX_DAG_OWNER='***' AIRFLOW_CTX_DAG_ID='covid_wave_3_etl' AIRFLOW_CTX_TASK_ID='load' AIRFLOW_CTX_EXECUTION_DATE='2024-09-01T00:00:00+00:00' AIRFLOW_CTX_TRY_NUMBER='2' AIRFLOW_CTX_DAG_RUN_ID='scheduled__2024-09-01T00:00:00+00:00'
[2024-10-20T17:14:40.492+0000] {logging_mixin.py:154} INFO - Error loading data to database: [Errno 2] No such file or directory: '/opt/***/data/round-3-line.csv'
[2024-10-20T17:14:40.493+0000] {taskinstance.py:1937} ERROR - Task failed with exception
Traceback (most recent call last):
  File "/home/airflow/.local/lib/python3.8/site-packages/airflow/operators/python.py", line 192, in execute
    return_value = self.execute_callable()
  File "/home/airflow/.local/lib/python3.8/site-packages/airflow/operators/python.py", line 209, in execute_callable
    return self.python_callable(*self.op_args, **self.op_kwargs)
  File "/opt/airflow/dags/covid_wave_3.py", line 38, in load_to_db
    df = pd.read_csv(data_path)
  File "/home/airflow/.local/lib/python3.8/site-packages/pandas/io/parsers/readers.py", line 912, in read_csv
    return _read(filepath_or_buffer, kwds)
  File "/home/airflow/.local/lib/python3.8/site-packages/pandas/io/parsers/readers.py", line 577, in _read
    parser = TextFileReader(filepath_or_buffer, **kwds)
  File "/home/airflow/.local/lib/python3.8/site-packages/pandas/io/parsers/readers.py", line 1407, in __init__
    self._engine = self._make_engine(f, self.engine)
  File "/home/airflow/.local/lib/python3.8/site-packages/pandas/io/parsers/readers.py", line 1661, in _make_engine
    self.handles = get_handle(
  File "/home/airflow/.local/lib/python3.8/site-packages/pandas/io/common.py", line 859, in get_handle
    handle = open(
FileNotFoundError: [Errno 2] No such file or directory: '/opt/airflow/data/round-3-line.csv'
[2024-10-20T17:14:40.508+0000] {taskinstance.py:1400} INFO - Marking task as FAILED. dag_id=covid_wave_3_etl, task_id=load, execution_date=20240901T000000, start_date=20241020T171440, end_date=20241020T171440
[2024-10-20T17:14:40.523+0000] {standard_task_runner.py:104} ERROR - Failed to execute job 586 for task load ([Errno 2] No such file or directory: '/opt/airflow/data/round-3-line.csv'; 93)
[2024-10-20T17:14:40.571+0000] {local_task_job_runner.py:228} INFO - Task exited with return code 1
[2024-10-20T17:14:40.600+0000] {taskinstance.py:2778} INFO - 0 downstream tasks scheduled from follow-on schedule check
